<?xml version="1.0"?>
<robot xmlns:xacro="http://www.ros.org/wiki/xacro"  name="robot">
<link name="base_link">
</link>
<joint name="chassis_joint" type="fixed">
    <parent link="base_link"/>
    <child link="chassis"/>
    <origin xyz="0 0 0"/>
</joint>
<link name="chassis">
    <visual>
      <geometry>
        <box size="0.33 0.20 0.09"/> <!-- Length 330mm, width estimated 250mm, height 90mm -->
      </geometry>
      <material name="yellow">
        <color rgba="1 1 0 1"/>
      </material>
    </visual>
    <collision>
      <geometry>
        <box size="0.33 0.25 0.09"/>
      </geometry>
    </collision>
    <inertial>
      <mass value="5.0"/>
      <origin xyz="0 0 0"/>
      <inertia ixx="0.1" ixy="0.0" ixz="0.0" iyy="0.1" iyz="0.0" izz="0.1"/>
    </inertial>
  </link>

  <!-- Front-Left Wheel -->
  <link name="wheel_fl">
    <visual>
	  <origin rpy="1.570795 0 0" xyz="0 0 0"/>
      <geometry>
        <cylinder length="0.04" radius="0.06"/> <!-- Diameter 120mm, height 40mm -->
      </geometry>
      <material name="green">
        <color rgba="0 1 0 1"/>
      </material>
    </visual>
    <collision>
      <geometry>
        <cylinder length="0.04" radius="0.06"/>
      </geometry>
    </collision>
    <inertial>
      <mass value="0.5"/>
      <origin xyz="0 0 0"/>
      <inertia ixx="0.01" ixy="0.0" ixz="0.0" iyy="0.01" iyz="0.0" izz="0.01"/>
    </inertial>
  </link>

  <joint name="joint_wheel_fl" type="continuous">
    <parent link="chassis"/>
    <child link="wheel_fl"/>
    <origin xyz="0.14 0.12 -0.045" rpy="0 0 0"/> <!-- Rotate the wheel to make it perpendicular -->
    <axis xyz="0 1 0"/>
  </joint>

  <!-- Front-Right Wheel -->
  <link name="wheel_fr">
    <visual>
	  <origin rpy="1.570795 0 0" xyz="0 0 0"/>
      <geometry>
        <cylinder length="0.04" radius="0.06"/> <!-- Diameter 120mm, height 40mm -->
      </geometry>
      <material name="green">
        <color rgba="0 1 0 1"/>
      </material>
    </visual>
    <collision>
      <geometry>
        <cylinder length="0.04" radius="0.06"/>
      </geometry>
    </collision>
    <inertial>
      <mass value="0.5"/>
      <origin xyz="0 0 0"/>
      <inertia ixx="0.01" ixy="0.0" ixz="0.0" iyy="0.01" iyz="0.0" izz="0.01"/>
    </inertial>
  </link>

  <joint name="joint_wheel_fr" type="continuous">
    <parent link="chassis"/>
    <child link="wheel_fr"/>
    <origin xyz="0.14 -0.12 -0.045" rpy="0 1.57 0"/> <!-- Rotate the wheel to make it perpendicular -->
    <axis xyz="0 1 0"/>
  </joint>

  <!-- Rear-Left Wheel -->
  <link name="wheel_rl">
    <visual>
	  <origin rpy="1.570795 0 0" xyz="0 0 0"/>
      <geometry>
        <cylinder length="0.04" radius="0.06"/> <!-- Diameter 120mm, height 40mm -->
      </geometry>
      <material name="green">
        <color rgba="0 1 0 1"/>
      </material>
    </visual>
    <collision>
      <geometry>
        <cylinder length="0.04" radius="0.06"/>
      </geometry>
    </collision>
    <inertial>
      <mass value="0.5"/>
      <origin xyz="0 0 0"/>
      <inertia ixx="0.01" ixy="0.0" ixz="0.0" iyy="0.01" iyz="0.0" izz="0.01"/>
    </inertial>
  </link>

  <joint name="joint_wheel_rl" type="continuous">
    <parent link="chassis"/>
    <child link="wheel_rl"/>
    <origin xyz="-0.14 0.12 -0.045" rpy="0 1.57 0"/> <!-- Rotate the wheel to make it perpendicular -->
    <axis xyz="0 1 0"/>
  </joint>

  <!-- Rear-Right Wheel -->
  <link name="wheel_rr">
    <visual>
	  <origin rpy="1.570795 0 0" xyz="0 0 0"/>
      <geometry>
        <cylinder length="0.04" radius="0.06"/> <!-- Diameter 120mm, height 40mm -->
      </geometry>
      <material name="green">
        <color rgba="0 1 0 1"/>
      </material>
    </visual>
    <collision>
      <geometry>
        <cylinder length="0.04" radius="0.06"/>
      </geometry>
    </collision>
    <inertial>
      <mass value="0.5"/>
      <origin xyz="0 0 0"/>
      <inertia ixx="0.01" ixy="0.0" ixz="0.0" iyy="0.01" iyz="0.0" izz="0.01"/>
    </inertial>
  </link>

  <joint name="joint_wheel_rr" type="continuous">
    <parent link="chassis"/>
    <child link="wheel_rr"/>
    <origin xyz="-0.14 -0.12 -0.045" rpy="0 1.57 0"/> <!-- Rotate the wheel to make it perpendicular -->
    <axis xyz="0 1 0"/>
  </joint>

  <!-- Tower on top -->
  <link name="tower">
    <visual>
      <geometry>
        <box size="0.1 0.1 0.31"/> <!-- Approximate width and length, height 310mm -->
      </geometry>
      <material name="black">
        <color rgba="0 0 0 1"/>
      </material>
    </visual>
    <collision>
      <geometry>
        <box size="0.1 0.1 0.31"/>
      </geometry>
    </collision>
    <inertial>
      <mass value="1.0"/>
      <origin xyz="0 0 0"/>
      <inertia ixx="0.01" ixy="0.0" ixz="0.0" iyy="0.01" iyz="0.0" izz="0.01"/>
    </inertial>
  </link>

  <joint name="joint_tower" type="fixed">
    <parent link="chassis"/>
    <child link="tower"/>
    <origin xyz="-0.1 0 0.14" rpy="0 0 0"/>
  </joint>

  <joint name="laser_joint" type="fixed">
        <parent link="tower"/>
        <child link="laser_frame"/>
        <origin xyz="0 0 0.17" rpy="0 0 0"/>
  </joint>

  <link name="laser_frame">
    <visual>
        <geometry>
            <cylinder radius="0.05" length="0.04"/>
        </geometry>
        <material name="red"/>
    </visual>
  </link>

  <material name="red">
    <color rgba="1 0 0 1"/>
  </material>


</robot>